[INFO   ] Logger: Record log in /storage/emulated/0/.2/MyTransportApp-main/.kivy/logs/kivy_21-11-28_92.txt
[INFO   ] Kivy: v2.0.0
[INFO   ] Kivy: Installed at "/data/user/0/ru.iiec.pydroid3/files/aarch64-linux-android/lib/python3.9/site-packages/kivy/__init__.py"
[INFO   ] Python: v3.9.7 (default, Oct  6 2021, 01:34:26) 
[GCC 11.1.0]
[INFO   ] Python: Interpreter at "/data/user/0/ru.iiec.pydroid3/files/aarch64-linux-android/bin/python3"
[INFO   ] KivyMD: v0.103.0
[INFO   ] Factory: 186 symbols loaded
[INFO   ] Image: Providers: img_tex, img_dds, img_sdl2, img_pil (img_ffpyplayer ignored)
[INFO   ] Window: Provider: sdl2
[INFO   ] GL: Using the "OpenGL ES 2" graphics system
[INFO   ] GL: Backend used <sdl2>
[INFO   ] GL: OpenGL version <b'OpenGL ES 3.2 build 1.13@5776728'>
[INFO   ] GL: OpenGL vendor <b'Imagination Technologies'>
[INFO   ] GL: OpenGL renderer <b'PowerVR Rogue GE8320'>
[INFO   ] GL: OpenGL parsed version: 3, 2
[INFO   ] GL: Texture max size <8192>
[INFO   ] GL: Texture max units <16>
[INFO   ] Window: auto add sdl2 input provider
[INFO   ] Window: virtual keyboard not allowed, single mode, not docked
[INFO   ] Text: Provider: sdl2
[INFO   ] GL: NPOT texture support is available
[INFO   ] Loader: using a thread pool of 2 workers
[WARNING] Base: Unknown <android> provider
[INFO   ] Base: Start application main loop
[WARNING] stderr: Traceback (most recent call last):
[WARNING] stderr:   File "/data/user/0/ru.iiec.pydroid3/files/aarch64-linux-android/lib/python3.9/site-packages/urllib3/response.py", line 438, in _error_catcher
[WARNING] stderr:     yield
[WARNING] stderr:   File "/data/user/0/ru.iiec.pydroid3/files/aarch64-linux-android/lib/python3.9/site-packages/urllib3/response.py", line 519, in read
[WARNING] stderr:     data = self._fp.read(amt) if not fp_closed else b""
[WARNING] stderr:   File "/data/user/0/ru.iiec.pydroid3/files/aarch64-linux-android/lib/python3.9/http/client.py", line 462, in read
[WARNING] stderr:     n = self.readinto(b)
[WARNING] stderr:   File "/data/user/0/ru.iiec.pydroid3/files/aarch64-linux-android/lib/python3.9/http/client.py", line 506, in readinto
[WARNING] stderr:     n = self.fp.readinto(b)
[WARNING] stderr:   File "/data/user/0/ru.iiec.pydroid3/files/aarch64-linux-android/lib/python3.9/socket.py", line 704, in readinto
[WARNING] stderr:     return self._sock.recv_into(b)
[WARNING] stderr: socket.timeout: timed out
[WARNING] stderr: 
[WARNING] stderr: During handling of the above exception, another exception occurred:
[WARNING] stderr: 
[WARNING] stderr: Traceback (most recent call last):
[WARNING] stderr:   File "/data/user/0/ru.iiec.pydroid3/files/aarch64-linux-android/lib/python3.9/site-packages/requests/models.py", line 758, in generate
[WARNING] stderr:     for chunk in self.raw.stream(chunk_size, decode_content=True):
[WARNING] stderr:   File "/data/user/0/ru.iiec.pydroid3/files/aarch64-linux-android/lib/python3.9/site-packages/urllib3/response.py", line 576, in stream
[WARNING] stderr:     data = self.read(amt=amt, decode_content=decode_content)
[WARNING] stderr:   File "/data/user/0/ru.iiec.pydroid3/files/aarch64-linux-android/lib/python3.9/site-packages/urllib3/response.py", line 541, in read
[WARNING] stderr:     raise IncompleteRead(self._fp_bytes_read, self.length_remaining)
[WARNING] stderr:   File "/data/user/0/ru.iiec.pydroid3/files/aarch64-linux-android/lib/python3.9/contextlib.py", line 137, in __exit__
[WARNING] stderr:     self.gen.throw(typ, value, traceback)
[WARNING] stderr:   File "/data/user/0/ru.iiec.pydroid3/files/aarch64-linux-android/lib/python3.9/site-packages/urllib3/response.py", line 443, in _error_catcher
[WARNING] stderr:     raise ReadTimeoutError(self._pool, None, "Read timed out.")
[WARNING] stderr: urllib3.exceptions.ReadTimeoutError: HTTPConnectionPool(host='c.tile.openstreetmap.org', port=80): Read timed out.
[WARNING] stderr: 
[WARNING] stderr: During handling of the above exception, another exception occurred:
[WARNING] stderr: 
[WARNING] stderr: Traceback (most recent call last):
[WARNING] stderr:   File "/data/user/0/ru.iiec.pydroid3/files/aarch64-linux-android/lib/python3.9/site-packages/kivy_garden/mapview/downloader.py", line 107, in _check_executor
[WARNING] stderr:     result = future.result()
[WARNING] stderr:   File "/data/user/0/ru.iiec.pydroid3/files/aarch64-linux-android/lib/python3.9/concurrent/futures/_base.py", line 438, in result
[WARNING] stderr:     return self.__get_result()
[WARNING] stderr:   File "/data/user/0/ru.iiec.pydroid3/files/aarch64-linux-android/lib/python3.9/concurrent/futures/_base.py", line 390, in __get_result
[WARNING] stderr:     raise self._exception
[WARNING] stderr:   File "/data/user/0/ru.iiec.pydroid3/files/aarch64-linux-android/lib/python3.9/concurrent/futures/thread.py", line 52, in run
[WARNING] stderr:     result = self.fn(*self.args, **self.kwargs)
[WARNING] stderr:   File "/data/user/0/ru.iiec.pydroid3/files/aarch64-linux-android/lib/python3.9/site-packages/kivy_garden/mapview/downloader.py", line 90, in _load_tile
[WARNING] stderr:     response = requests.get(uri, headers={'User-agent': USER_AGENT}, timeout=5)
[WARNING] stderr:   File "/data/user/0/ru.iiec.pydroid3/files/aarch64-linux-android/lib/python3.9/site-packages/requests/api.py", line 75, in get
[WARNING] stderr:     return request('get', url, params=params, **kwargs)
[WARNING] stderr:   File "/data/user/0/ru.iiec.pydroid3/files/aarch64-linux-android/lib/python3.9/site-packages/requests/api.py", line 61, in request
[WARNING] stderr:     return session.request(method=method, url=url, **kwargs)
[WARNING] stderr:   File "/data/user/0/ru.iiec.pydroid3/files/aarch64-linux-android/lib/python3.9/site-packages/requests/sessions.py", line 542, in request
[WARNING] stderr:     resp = self.send(prep, **send_kwargs)
[WARNING] stderr:   File "/data/user/0/ru.iiec.pydroid3/files/aarch64-linux-android/lib/python3.9/site-packages/requests/sessions.py", line 697, in send
[WARNING] stderr:     r.content
[WARNING] stderr:   File "/data/user/0/ru.iiec.pydroid3/files/aarch64-linux-android/lib/python3.9/site-packages/requests/models.py", line 836, in content
[WARNING] stderr:     self._content = b''.join(self.iter_content(CONTENT_CHUNK_SIZE)) or b''
[WARNING] stderr:   File "/data/user/0/ru.iiec.pydroid3/files/aarch64-linux-android/lib/python3.9/site-packages/requests/models.py", line 765, in generate
[WARNING] stderr:     raise ConnectionError(e)
[WARNING] stderr: requests.exceptions.ConnectionError: HTTPConnectionPool(host='c.tile.openstreetmap.org', port=80): Read timed out.
